## 配置

### 数据库连接池

#### hikari

##### 使用了数据库端已经超时的连接，验证失败，导致超时

报错如下：

```java
2020-07-14 11:58:38.036  WARN 251412 --- [nio-8085-exec-5] c.z.h.p.PoolBase                         : HikariPool-1 - Failed to validate connection 
com.mysql.cj.jdbc.ConnectionImpl@795d15b3 (No operations allowed after connection closed.). Possibly consider using a shorter maxLifetime value.
org.springframework.transaction.CannotCreateTransactionException: Could not open JDBC Connection for transaction; nested exception is java.sql.SQLTransientConnectionException: HikariPool-1 - Connection is not available, request timed out after 10013ms.
	at org.springframework.jdbc.datasource.DataSourceTransactionManager.doBegin(DataSourceTransactionManager.java:308) ~[spring-jdbc-5.2.5.RELEASE.jar:5.2.5.RELEASE]
	at org.springframework.transaction.support.AbstractPlatformTransactionManager.startTransaction(AbstractPlatformTransactionManager.java:400) ~[spring-tx-5.2.5.RELEASE.jar:5.2.5.RELEASE]
	at org.springframework.transaction.support.AbstractPlatformTransactionManager.getTransaction(AbstractPlatformTransactionManager.java:373) ~[spring-tx-5.2.5.RELEASE.jar:5.2.5.RELEASE]
	at org.springframework.transaction.interceptor.TransactionAspectSupport.createTransactionIfNecessary(TransactionAspectSupport.java:572) ~[spring-tx-5.2.5.RELEASE.jar:5.2.5.RELEASE]
	at org.springframework.transaction.interceptor.TransactionAspectSupport.invokeWithinTransaction(TransactionAspectSupport.java:360) ~[spring-tx-5.2.5.RELEASE.jar:5.2.5.RELEASE]
	at org.springframework.transaction.interceptor.TransactionInterceptor.invoke(TransactionInterceptor.java:118) ~[spring-tx-5.2.5.RELEASE.jar:5.2.5.RELEASE]
	at org.springframework.aop.framework.ReflectiveMethodInvocation.proceed(ReflectiveMethodInvocation.java:186) ~[spring-aop-5.2.5.RELEASE.jar:5.2.5.RELEASE]
	at org.springframework.aop.framework.CglibAopProxy$CglibMethodInvocation.proceed(CglibAopProxy.java:749) ~[spring-aop-5.2.5.RELEASE.jar:5.2.5.RELEASE]
	at org.springframework.aop.framework.CglibAopProxy$DynamicAdvisedInterceptor.intercept(CglibAopProxy.java:691) ~[spring-aop-5.2.5.RELEASE.jar:5.2.5.RELEASE]
```

原因是连接池配置的问题，一般情况下会根据数据库的配置去做连接池的配置，具体的配置项为

1. idle-timeout：一个连接idle状态的最大时长（毫秒），超时则被释放（retired），缺省:10分钟
2. maxLifetime：一个连接的生命时长（毫秒），超时而且没被使用则被释放（retired），缺省:30分钟，建议设置比数据库超时时长少30秒，参考MySQL wait_timeout参数

但是此处hikari有个校验条件：idleTimeout+1秒 > maxLifetime 且 maxLifetime > 0，idle-timeout则会被重置为0（代表永远不会退出）；

此处我踩得坑为未设置maxLifetime，却设置了idle-timeout为30S，此时maxLifetime使用默认值30S，则会触发校验，使idle-timeout则会被重置为0

```yaml
hikari:
  auto-commit: true
  allow-pool-suspension: true
  data-source-properties:
    cachePrepStmts: true
    prepStmtCacheSize: 250
    prepStmtCacheSqlLimit: 2048
    useServerPrepStmts: true
  connection-timeout: 10000
  maximum-pool-size: 100
  minimum-idle: 5
  idle-timeout: 30000
  max-lifetime: 50000
```

## 线程池

### 异常日志打印

在测试中，发现通过自定义线程池实现的异步调用，即使异步执行的代码中抛出了异常，也不会打印出异常栈。

首先，看看线程池是如何配置的：

```java
//直接使用ThreadPoolExecutor
private static final ThreadPoolExecutor orderSaleExecutor = new ThreadPoolExecutor(4,200,10, TimeUnit.SECONDS, new ArrayBlockingQueue<Runnable>(200), new ThreadPoolExecutor.AbortPolicy());

public static ThreadPoolExecutor getOrderSaleExecutor() {
    return orderSaleExecutor;
}
```

然后，异步方法的调用，有两种方式

```java
//调用submit方法
ThreadPoolUtils.getOrderSaleExecutor().submit(() -> this.handleBusiness());
//调用execute方法
ThreadPoolUtils.getOrderSaleExecutor().execute(() -> this.handleBusiness());
```

#### 原因

##### 1 线程池执行代码

先来看看，为什么没有打印出异常栈，找到线程池执行任务的代码：

```java
//java.util.concurrent.ThreadPoolExecutor#runWorker
final void runWorker(Worker w) {
    Thread wt = Thread.currentThread();
    Runnable task = w.firstTask;
    w.firstTask = null;
    w.unlock(); // allow interrupts
    boolean completedAbruptly = true;
    try {
        while (task != null || (task = getTask()) != null) {
            w.lock();
            // If pool is stopping, ensure thread is interrupted;
            // if not, ensure thread is not interrupted.  This
            // requires a recheck in second case to deal with
            // shutdownNow race while clearing interrupt
            if ((runStateAtLeast(ctl.get(), STOP) ||
                 (Thread.interrupted() &&
                  runStateAtLeast(ctl.get(), STOP))) &&
                !wt.isInterrupted())
                wt.interrupt();
            try {
                beforeExecute(wt, task);
                Throwable thrown = null;
                try {
                    //将task的run方法try-catch住，将全部异常都捕获后，向上抛出，并能够执行afterExecute()回调方法
                    task.run();
                } catch (RuntimeException x) {
                    thrown = x; throw x;
                } catch (Error x) {
                    thrown = x; throw x;
                } catch (Throwable x) {
                    thrown = x; throw new Error(x);
                } finally {
                    afterExecute(task, thrown);
                }
            } finally {
                task = null;
                w.completedTasks++;
                w.unlock();
            }
        }
        completedAbruptly = false;
    } finally {
        processWorkerExit(w, completedAbruptly);
    }
}
//再看到，java.util.concurrent.ThreadPoolExecutor#afterExecute，ThreadPoolExecutor中的默认实现为空
protected void afterExecute(Runnable r, Throwable t) { }
```

所以，此处可以看出，在异常抛出后，并没有进行打印日志等操作。

##### 2 线程异常处理

线程是自带异常处理的，这里需要看到Thread类中的uncaughtExceptionHandler、defaultUncaughtExceptionHandler字段，都是java.lang.Thread.UncaughtExceptionHandler的类型，先看看这个接口是干嘛的。

```java
/**
 * Interface for handlers invoked when a <tt>Thread</tt> abruptly
 * terminates due to an uncaught exception.
 * <p>When a thread is about to terminate due to an uncaught exception
 * the Java Virtual Machine will query the thread for its
 * <tt>UncaughtExceptionHandler</tt> using
 * {@link #getUncaughtExceptionHandler} and will invoke the handler's
 * <tt>uncaughtException</tt> method, passing the thread and the
 * exception as arguments.
 * If a thread has not had its <tt>UncaughtExceptionHandler</tt>
 * explicitly set, then its <tt>ThreadGroup</tt> object acts as its
 * <tt>UncaughtExceptionHandler</tt>. If the <tt>ThreadGroup</tt> object
 * has no
 * special requirements for dealing with the exception, it can forward
 * the invocation to the {@linkplain #getDefaultUncaughtExceptionHandler
 * default uncaught exception handler}.
 *
 * @see #setDefaultUncaughtExceptionHandler
 * @see #setUncaughtExceptionHandler
 * @see ThreadGroup#uncaughtException
 * @since 1.5
 */
@FunctionalInterface
public interface UncaughtExceptionHandler {
    /**
     * Method invoked when the given thread terminates due to the
     * given uncaught exception.
     * <p>Any exception thrown by this method will be ignored by the
     * Java Virtual Machine.
     * @param t the thread
     * @param e the exception
     */
    void uncaughtException(Thread t, Throwable e);
}
```

注释已经写得很明白了

1. 当线程因为未捕获的异常终止时，会调用该接口的uncaughtException方法

2. 所使用的的Handler顺序为：线程持有的uncaughtExceptionHandler > group线程组中的默认Handler

   此处线程组中的默认handler其实也是通过getDefaultUncaughtExceptionHandler方法获取线程的默认Handler

那该方法啥时候调用呢，继续看源码

```java
//首先获取ExceptionHandler，验证了上述的顺序
public UncaughtExceptionHandler getUncaughtExceptionHandler() {
    return uncaughtExceptionHandler != null ?
        uncaughtExceptionHandler : group;
}

/**
 * Dispatch an uncaught exception to the handler. This method is
 * intended to be called only by the JVM.
 */
//实际调用uncaughtException的方法，可以看到这个方法其实是私有的，在源码中也并没看到调用。看完注释才发现，此方法仅被JVM调用，应该是线程抛出异常后，JVM在获取异常的时候所调用
private void dispatchUncaughtException(Throwable e) {
    getUncaughtExceptionHandler().uncaughtException(this, e);
}
```

#### 解决方案

逻辑很简单，只要在线程抛出异常时，拿到这个异常并打印日志即可。百度了一下，发现线程和线程池提供了几种异常处理机制。

1. 上面看到的ThreadPoolExecutor#afterExecute()方法，可以通过继承ThreadPoolExecutor类，重写afterExecute方法，实现异常处理

   ```java
   @Slf4j
   public class CustomThreadPoolExecutor extends ThreadPoolExecutor {
   
       public CustomThreadPoolExecutor(int corePoolSize, int maximumPoolSize, long keepAliveTime, TimeUnit unit, BlockingQueue<Runnable> workQueue, ThreadFactory threadFactory) {
           super(corePoolSize, maximumPoolSize, keepAliveTime, unit, workQueue, threadFactory);
       }
   
       public CustomThreadPoolExecutor(int corePoolSize, int maximumPoolSize, long keepAliveTime, TimeUnit unit, BlockingQueue<Runnable> workQueue, RejectedExecutionHandler handler) {
           super(corePoolSize, maximumPoolSize, keepAliveTime, unit, workQueue, handler);
       }
   
       public CustomThreadPoolExecutor(int corePoolSize, int maximumPoolSize, long keepAliveTime, TimeUnit unit, BlockingQueue<Runnable> workQueue, ThreadFactory threadFactory, RejectedExecutionHandler handler) {
           super(corePoolSize, maximumPoolSize, keepAliveTime, unit, workQueue, threadFactory, handler);
       }
   
       public CustomThreadPoolExecutor(int corePoolSize, int maximumPoolSize, long keepAliveTime, TimeUnit unit, BlockingQueue<Runnable> workQueue) {
           super(corePoolSize, maximumPoolSize, keepAliveTime, unit, workQueue);
       }
   
       /**
        * 重写回调方法，打印异常栈
        * @param r
        * @param t
        */
       @Override
       protected void afterExecute(Runnable r, Throwable t) {
           super.afterExecute(r, t);
           //存在错误，打印到日志
           if(r instanceof FutureTask){
               //调用submit方法，会包装成FutureTask，异常被包装成ExecutionException，不会直接抛出
               // java.util.concurrent.AbstractExecutorService.submit(java.util.concurrent.Callable<T>)
               try{
                   ((FutureTask) r).get();
               }catch (Throwable taskThr){
                   log.error("线程执行异常：",taskThr);
               }
           }
           if(t != null){
               //调用execute方法，可以直接获取到异常
               //java.util.concurrent.ThreadPoolExecutor.execute
               log.error("线程执行异常：",t);
           }
       }
   }
   ```

2. 自定义UncaughtExceptionHandler，并设置到线程中

   ```java
   //这里参考一下org.apache.commons.lang3.concurrent.BasicThreadFactory的实现
   private void initializeThread(final Thread thread) {
   
       if (getNamingPattern() != null) {
           final Long count = Long.valueOf(threadCounter.incrementAndGet());
           thread.setName(String.format(getNamingPattern(), count));
       }
   	//设置uncaughtExceptionHandler
       if (getUncaughtExceptionHandler() != null) {
           thread.setUncaughtExceptionHandler(getUncaughtExceptionHandler());
       }
   
       if (getPriority() != null) {
           thread.setPriority(getPriority().intValue());
       }
   
       if (getDaemonFlag() != null) {
           thread.setDaemon(getDaemonFlag().booleanValue());
       }
   }
   
   //创建线程池的时候，使用带有ThreadFactory的构造方法，并塞一个UncaughtExceptionHandler到ThreadFactory中
       private static final ThreadPoolExecutor errorLogExecutor = new ThreadPoolExecutor(4, 4, 0, TimeUnit.SECONDS, new LinkedBlockingQueue<>(),
               (new BasicThreadFactory.Builder())
                       .uncaughtExceptionHandler(new Thread.UncaughtExceptionHandler() {
                           @Override
                           public void uncaughtException(Thread t, Throwable e) {
                               log.error("线程异常", e);
                           }
                       })
                       .build()
               , new ThreadPoolExecutor.AbortPolicy());
   ```

#### 测试&总结

测试较简单，使用我们自定义的线程池，然后在任务中throw一个异常，看看日志是否记录即可

测试结果结果如下：

1、execute方法

2020-07-27 11:12:08.682 ERROR 79744 --- [mer-thread-pool] c.y.o.c.t.CustomUncaughtExceptionHandler : 线程执行异常

java.lang.NullPointerException: null
	at com.ygp.oms.openapi.api.service.impl.SignInnerServiceTest.lambda$m0$0(SignInnerServiceTest.java:35) ~[test-classes/:?]
	at java.util.concurrent.ThreadPoolExecutor.runWorker(ThreadPoolExecutor.java:1149) ~[?:1.8.0_191]
	at java.util.concurrent.ThreadPoolExecutor$Worker.run(ThreadPoolExecutor.java:624) ~[?:1.8.0_191]
	at java.lang.Thread.run(Thread.java:748) [?:1.8.0_191]

2、submit方法

2020-07-27 11:12:14.793 ERROR 79744 --- [pool-4-thread-1] c.y.o.c.t.CustomThreadPoolExecutor       : 线程执行异常：

java.util.concurrent.ExecutionException: java.lang.NullPointerException
	at java.util.concurrent.FutureTask.report(FutureTask.java:122) ~[?:1.8.0_191]
	at java.util.concurrent.FutureTask.get(FutureTask.java:192) ~[?:1.8.0_191]
	at com.ygp.oms.common.thread.CustomThreadPoolExecutor.afterExecute(CustomThreadPoolExecutor.java:36) [classes/:?]
	at java.util.concurrent.ThreadPoolExecutor.runWorker(ThreadPoolExecutor.java:1157) [?:1.8.0_191]
	at java.util.concurrent.ThreadPoolExecutor$Worker.run(ThreadPoolExecutor.java:624) [?:1.8.0_191]
	at java.lang.Thread.run(Thread.java:748) [?:1.8.0_191]
Caused by: java.lang.NullPointerException
	at com.ygp.oms.openapi.api.service.impl.SignInnerServiceTest.lambda$m0$2(SignInnerServiceTest.java:45) ~[test-classes/:?]
	at java.util.concurrent.FutureTask.run$$$capture(FutureTask.java:266) ~[?:1.8.0_191]
	at java.util.concurrent.FutureTask.run(FutureTask.java) ~[?:1.8.0_191]
	at java.util.concurrent.ThreadPoolExecutor.runWorker(ThreadPoolExecutor.java:1149) ~[?:1.8.0_191]
	... 2 more

但这里其实还有一个坑，那就是上述的解决方案2的自定义UncaughtExceptionHandler对于submit并不生效，这是为什么呢，让我们看看submit方法的源码。

```java
public <T> Future<T> submit(Runnable task, T result) {
    if (task == null) throw new NullPointerException();
    RunnableFuture<T> ftask = newTaskFor(task, result);
    execute(ftask);
    return ftask;
}
//包装成FutureTask
protected <T> RunnableFuture<T> newTaskFor(Runnable runnable, T value) {
    return new FutureTask<T>(runnable, value);
}
```

可以看到，submit方法因为可以返回一个计算结果，所以包装成了FutureTask，继续看FutureTask的源码

```java
public void run() {
    if (state != NEW ||
        !UNSAFE.compareAndSwapObject(this, runnerOffset,
                                     null, Thread.currentThread()))
        return;
    try {
        Callable<V> c = callable;
        if (c != null && state == NEW) {
            V result;
            boolean ran;
            try {
                //实际执行任务的地方
                result = c.call();
                ran = true;
            } catch (Throwable ex) {
                result = null;
                ran = false;
                //捕获所有的异常，并处理
                setException(ex);
            }
            if (ran)
                set(result);
        }
    } finally {
        // runner must be non-null until state is settled to
        // prevent concurrent calls to run()
        runner = null;
        // state must be re-read after nulling runner to prevent
        // leaked interrupts
        int s = state;
        if (s >= INTERRUPTING)
            handlePossibleCancellationInterrupt(s);
    }
}

/** The result to return or exception to throw from get() */
private Object outcome;

//处理异常
protected void setException(Throwable t) {
    if (UNSAFE.compareAndSwapInt(this, stateOffset, NEW, COMPLETING)) {
		//可以看到，将异常放到了outcome，并没有抛出
        outcome = t;
        UNSAFE.putOrderedInt(this, stateOffset, EXCEPTIONAL); // final state
        finishCompletion();
    }
}

/**
 * @throws CancellationException {@inheritDoc}
 */
public V get() throws InterruptedException, ExecutionException {
    int s = state;
    if (s <= COMPLETING)
        s = awaitDone(false, 0L);
    return report(s);
}

/**
 * @throws CancellationException {@inheritDoc}
 */
public V get(long timeout, TimeUnit unit)
    throws InterruptedException, ExecutionException, TimeoutException {
    if (unit == null)
        throw new NullPointerException();
    int s = state;
    if (s <= COMPLETING &&
        (s = awaitDone(true, unit.toNanos(timeout))) <= COMPLETING)
        throw new TimeoutException();
    return report(s);
}
private V report(int s) throws ExecutionException {
    Object x = outcome;
    if (s == NORMAL)
        return (V)x;
    if (s >= CANCELLED)
        throw new CancellationException();
    throw new ExecutionException((Throwable)x);
}
```

可以看到，FutureTask中将异常放到了outcome，并且在get()方法中，会将异常包装成ExecutionException异常，并抛出。所以如果没有调用get()方法的话，该线程是不会抛出异常的，JVM并不会感知到该结果，所以此类异常用UncaughtExceptionHandler是捕获不到的。ps：这里的设计其实有点奇怪，猜测jdk开发是想使用submit方法的人，自己显示的去处理一些异常，而不是使用全局处理

##### 总结

1. ThreadPoolExecutor#afterExecute()，该回调方法可以支持拿到两种异常信息，但需要判断一下执行任务Runnable是否是FutureTask类型
2. FutureTask的get方法调用多次并不会影响，因此就算在自定义ThreadPoolExecutor中已经调用过get()，也不会影响到使用方获取计算结果
3. UncaughtExceptionHandler可以设置全局异常，此种针对线程异常结束，由JVM获取